<?xml version="1.0" ?>
<!-- Generated using onshape-to-robot -->
<!-- Onshape https://cad.onshape.com/documents/b36124d5af2122816059b47e/w/a841b9e213fb45aaaf3ccb90/e/a48504d4e6ba8d85418e90eb -->
<sdf version="1.7">
  <model name="Qbert">
    <!-- Link base -->
    <link name="base">
      <inertial>
        <pose>0.35 -0.45 0.148049 0 0 0</pose>
        <mass>87.2967</mass>
        <inertia>
          <ixx>16.0836</ixx>
          <ixy>7.94512e-15</ixy>
          <ixz>-4.63157e-16</ixz>
          <iyy>5.07096</iyy>
          <iyz>3.40439e-15</iyz>
          <izz>19.9385</izz>
        </inertia>
      </inertial>
      <pose>0 0 0 0 -0 0</pose>
      <!-- Part base_parts -->
      <visual name="base_parts_visual_mesh_1">
        <pose relative_to="base">0.35 -0.45 0.148049 0 -0 0</pose>
        <geometry>
          <mesh>
            <uri>model://Qbert/assets/merged/base_visual.stl</uri>
          </mesh>
        </geometry>
        <material>
          <ambient>0.439216 0.47451 0.501961 1</ambient>
          <diffuse>0.439216 0.47451 0.501961 1</diffuse>
          <specular>0.1 0.1 0.1 1</specular>
          <emissive>0 0 0 0</emissive>
        </material>
      </visual>
      <collision name="base_parts_collision_mesh_2">
        <pose relative_to="base">0.35 -0.45 0.148049 0 -0 0</pose>
        <geometry>
          <mesh>
            <uri>model://Qbert/assets/merged/base_collision.stl</uri>
          </mesh>
        </geometry>
      </collision>
    </link>
    <joint name="base_fixed_world" type="fixed">
      <parent>world</parent>
      <child>base</child>
    </joint>
    <!-- Link part_1 -->
    <link name="part_1">
      <inertial>
        <pose>-0.3 -0.0537638 2.77556e-17 0 0 0</pose>
        <mass>743.041</mass>
        <inertia>
          <ixx>21.4219</ixx>
          <ixy>2.27533e-15</ixy>
          <ixz>1.47955e-15</ixz>
          <iyy>63.2531</iyy>
          <iyz>8.51099e-16</iyz>
          <izz>64.8606</izz>
        </inertia>
      </inertial>
      <pose relative_to="J1Linear">0 0 0 0 -0 0</pose>
      <!-- Part part_1_parts -->
      <visual name="part_1_parts_visual_mesh_1">
        <pose relative_to="part_1">-0.3 -0.0537638 0 1.5708 -2.19831e-30 -1.36877e-27</pose>
        <geometry>
          <mesh>
            <uri>model://Qbert/assets/merged/part_1_visual.stl</uri>
          </mesh>
        </geometry>
        <material>
          <ambient>0.231373 0.380392 0.705882 1</ambient>
          <diffuse>0.231373 0.380392 0.705882 1</diffuse>
          <specular>0.1 0.1 0.1 1</specular>
          <emissive>0 0 0 0</emissive>
        </material>
      </visual>
      <collision name="part_1_parts_collision_mesh_2">
        <pose relative_to="part_1">-0.3 -0.0537638 0 1.5708 -2.19831e-30 -1.36877e-27</pose>
        <geometry>
          <mesh>
            <uri>model://Qbert/assets/merged/part_1_collision.stl</uri>
          </mesh>
        </geometry>
      </collision>
    </link>
    <!-- Link drum_assembly -->
    <link name="drum_assembly">
      <inertial>
        <pose>-9.68121e-17 -1.38104e-16 0.0677099 0 0 0</pose>
        <mass>168.749</mass>
        <inertia>
          <ixx>14.537</ixx>
          <ixy>-6.21542e-16</ixy>
          <ixz>-1.75415e-16</ixz>
          <iyy>14.537</iyy>
          <iyz>-1.73853e-15</iyz>
          <izz>12.1567</izz>
        </inertia>
      </inertial>
      <pose relative_to="J2Rotation">0 0 0 0 -0 0</pose>
      <!-- Part drum_assembly_parts -->
      <visual name="drum_assembly_parts_visual_mesh_1">
        <pose relative_to="drum_assembly">3.33067e-16 -9.99201e-16 0.0677099 1.5708 -3.86432e-18 2.98398</pose>
        <geometry>
          <mesh>
            <uri>model://Qbert/assets/merged/drum_assembly_visual.stl</uri>
          </mesh>
        </geometry>
        <material>
          <ambient>0.899365 0.679349 0.0913932 1</ambient>
          <diffuse>0.899365 0.679349 0.0913932 1</diffuse>
          <specular>0.1 0.1 0.1 1</specular>
          <emissive>0 0 0 0</emissive>
        </material>
      </visual>
      <collision name="drum_assembly_parts_collision_mesh_2">
        <pose relative_to="drum_assembly">3.33067e-16 -9.99201e-16 0.0677099 1.5708 -3.86432e-18 2.98398</pose>
        <geometry>
          <mesh>
            <uri>model://Qbert/assets/merged/drum_assembly_collision.stl</uri>
          </mesh>
        </geometry>
      </collision>
    </link>

    <joint name="camera_joint" type="fixed">
      <pose relative_to="drum_assembly">-0.127664 0.127727 0.345195 1.46442 0 0.785398</pose>
      <parent>drum_assembly</parent>
      <child>camera_link</child>
    </joint>
    <joint name="camera_optical_joint" type="fixed">
        <parent>camera_link</parent>
        <child>camera_optical_link</child>
    </joint>

    <link name="camera_link">
      <pose relative_to="camera_joint">0 0 0 0 0 0</pose>
      <sensor name="camera" type="camera">
        <pose>0 0 0 0 0 0</pose>
        <camera>
          <horizontal_fov>1.089</horizontal_fov>
          <image>
            <format>R8G8B8</format>
            <width>640</width>
            <height>480</height>
          </image>
          <clip>
            <near>0.5</near>
            <far>8.0</far>
          </clip>
        </camera>
        <always_on>true</always_on>
        <update_rate>30</update_rate>
        <visualize>true</visualize>
      </sensor>
    </link>
    <link name="camera_optical_link">
        <pose relative_to="camera_link">0 0 0 -1.5708 0 -1.5708</pose>
    </link>

    <!-- Joint from part_1 to drum_assembly -->
    <joint name="J2Rotation" type="revolute">
      <pose relative_to="part_1">-0.3 -0.38 -1.66533e-16 1.01309e-16 -2.0014e-17 -2.98398</pose>
      <parent>part_1</parent>
      <child>drum_assembly</child>
      <axis>
        <xyz>0 0 1</xyz>
        <limit>
          <effort>10</effort>
          <velocity>10</velocity>
          <lower>-3.141592653589793</lower>
          <upper>3.141592653589793</upper>
        </limit>
        <dynamics>
          <friction>0.0</friction>
          <damping>0.0</damping>
        </dynamics>
      </axis>
    </joint>
    <!-- Joint from base to part_1 -->
    <joint name="J1Linear" type="prismatic">
      <pose relative_to="base">0.65 -0.45 0.17 -1.5708 1.36877e-27 -2.19831e-30</pose>
      <parent>base</parent>
      <child>part_1</child>
      <axis>
        <xyz>0 0 1</xyz>
        <limit>
          <effort>10</effort>
          <velocity>10</velocity>
          <lower>-1</lower>
          <upper>1</upper>
        </limit>
        <dynamics>
          <friction>0.0</friction>
          <damping>0.0</damping>
        </dynamics>
      </axis>
    </joint>
  </model>
</sdf>
